<?xml version="1.0" ?>
<!-- =================================================================================== -->
<!-- |    This document was autogenerated by xacro from fetch_robotiq_hands.urdf.xacro | -->
<!-- |    EDITING THIS FILE BY HAND IS NOT RECOMMENDED                                 | -->
<!-- =================================================================================== -->
<robot name="fetch_robotiq_hands" xmlns:xacro="http://www.ros.org/wiki/xacro">
  <link name="base_link">
    <inertial>
      <origin rpy="0 0 0" xyz="-0.0036 0.0 0.0014"/>
      <mass value="70.1294"/>
      <inertia ixx="1.225" ixy="0.0099" ixz="0.0062" iyx="0.0099" iyy="1.2853" iyz="-0.0034" izx="0.0062" izy="-0.0034" izz="0.987"/>
    </inertial>
    <visual>
      <origin rpy="0 0 0" xyz="0 0 0"/>
      <geometry>
        <mesh filename="package://fetch_description/meshes/base_link.dae"/>
      </geometry>
      <material name="">
        <color rgba="0.356 0.361 0.376 1"/>
      </material>
    </visual>
    <collision>
      <origin rpy="0 0 0" xyz="0 0 0"/>
      <geometry>
        <mesh filename="package://fetch_description/meshes/base_link_collision.STL"/>
      </geometry>
    </collision>
  </link>
  <link name="r_wheel_link">
    <inertial>
      <origin rpy="0 0 0" xyz="0 0 0"/>
      <mass value="4.3542"/>
      <inertia ixx="0.0045" ixy="0" ixz="0" iyx="0" iyy="0.005" iyz="0" izx="0" izy="0" izz="0.0045"/>
    </inertial>
    <visual>
      <origin rpy="0 0 0" xyz="0 0 0"/>
      <geometry>
        <mesh filename="package://fetch_description/meshes/r_wheel_link.STL"/>
      </geometry>
      <material name="">
        <color rgba="0.086 0.506 0.767 1"/>
      </material>
    </visual>
    <collision>
      <origin rpy="0 0 0" xyz="0 0 0"/>
      <geometry>
        <mesh filename="package://fetch_description/meshes/r_wheel_link_collision.STL"/>
      </geometry>
    </collision>
  </link>
  <joint name="r_wheel_joint" type="continuous">
    <origin rpy="-6.123E-17 0 0" xyz="0.0012914 -0.18738 0.055325"/>
    <parent link="base_link"/>
    <child link="r_wheel_link"/>
    <axis xyz="0 1 0"/>
    <limit effort="8.85" velocity="17.4"/>
  </joint>
  <link name="l_wheel_link">
    <inertial>
      <origin rpy="0 0 0" xyz="0 0 0"/>
      <mass value="4.3542"/>
      <inertia ixx="0.0045" ixy="0" ixz="0" iyx="0" iyy="0.005" iyz="0" izx="0" izy="0" izz="0.0045"/>
    </inertial>
    <visual>
      <origin rpy="0 0 0" xyz="0 0 0"/>
      <geometry>
        <mesh filename="package://fetch_description/meshes/l_wheel_link.STL"/>
      </geometry>
      <material name="">
        <color rgba="0.086 0.506 0.767 1"/>
      </material>
    </visual>
    <collision>
      <origin rpy="0 0 0" xyz="0 0 0"/>
      <geometry>
        <mesh filename="package://fetch_description/meshes/l_wheel_link_collision.STL"/>
      </geometry>
    </collision>
  </link>
  <joint name="l_wheel_joint" type="continuous">
    <origin rpy="-6.123E-17 0 0" xyz="0.0012914 0.18738 0.055325"/>
    <parent link="base_link"/>
    <child link="l_wheel_link"/>
    <axis xyz="0 1 0"/>
    <limit effort="8.85" velocity="17.4"/>
  </joint>
  <link name="estop_link">
    <inertial>
      <origin rpy="0 0 0" xyz="0.002434512737072 -0.00330608315239905 0.00665139196650039"/>
      <mass value="0.00196130439134723"/>
      <inertia ixx="3.02810026604417E-07" ixy="-1.5862023118056E-08" ixz="3.16561396557437E-08" iyy="2.93322917127605E-07" iyz="-4.28833522751273E-08" izz="2.28513272627183E-07"/>
    </inertial>
    <visual>
      <origin rpy="0 0 0" xyz="0 0 0"/>
      <geometry>
        <mesh filename="package://fetch_description/meshes/estop_link.STL"/>
      </geometry>
      <material name="">
        <color rgba="0.8 0 0 1"/>
      </material>
    </visual>
    <collision>
      <origin rpy="0 0 0" xyz="0 0 0"/>
      <geometry>
        <mesh filename="package://fetch_description/meshes/estop_link.STL"/>
      </geometry>
    </collision>
  </link>
  <joint name="estop_joint" type="fixed">
    <origin rpy="1.5708 0 0" xyz="-0.12465 0.23892 0.31127"/>
    <parent link="base_link"/>
    <child link="estop_link"/>
    <axis xyz="0 0 0"/>
  </joint>
  <link name="laser_link">
    <inertial>
      <origin rpy="0 0 0" xyz="-0.0306228970175641 0.0007091682908278 0.0551974119471302"/>
      <mass value="0.00833634573995571"/>
      <inertia ixx="1.01866461240801E-06" ixy="-5.88447626567756E-08" ixz="7.83857244757914E-08" iyy="5.10039589974707E-07" iyz="-7.12664289617235E-09" izz="1.28270671527309E-06"/>
    </inertial>
    <visual>
      <origin rpy="0 0 0" xyz="0 0 0"/>
      <geometry>
        <mesh filename="package://fetch_description/meshes/laser_link.STL"/>
      </geometry>
      <material name="">
        <color rgba="0.792156862745098 0.819607843137255 0.933333333333333 1"/>
      </material>
    </visual>
    <collision>
      <origin rpy="0 0 0" xyz="0 0 0"/>
      <geometry>
        <mesh filename="package://fetch_description/meshes/laser_link.STL"/>
      </geometry>
    </collision>
  </link>
  <joint name="laser_joint" type="fixed">
    <origin rpy="3.1415 0 0" xyz="0.235 0 0.2878"/>
    <parent link="base_link"/>
    <child link="laser_link"/>
    <axis xyz="0 0 0"/>
  </joint>
  <link name="torso_lift_link">
    <inertial>
      <origin rpy="0 0 0" xyz="-0.0013 -0.0009 0.2935"/>
      <mass value="10.7796"/>
      <inertia ixx="0.3354" ixy="0.0" ixz="-0.0162" iyx="0.0" iyy="0.3354" iyz="-0.0006" izx="-0.0162" izy="-0.0006" izz="0.0954"/>
    </inertial>
    <visual>
      <origin rpy="0 0 0" xyz="0 0 0"/>
      <geometry>
        <mesh filename="package://fetch_description/meshes/torso_lift_link.dae"/>
      </geometry>
      <material name="">
        <color rgba="1 1 1 1"/>
      </material>
    </visual>
    <collision>
      <origin rpy="0 0 0" xyz="0 0 0"/>
      <geometry>
        <mesh filename="package://fetch_description/meshes/torso_lift_link_collision.STL"/>
      </geometry>
    </collision>
  </link>
  <joint name="torso_lift_joint" type="prismatic">
    <origin rpy="-6.123E-17 0 0" xyz="-0.086875 0 0.37743"/>
    <parent link="base_link"/>
    <child link="torso_lift_link"/>
    <axis xyz="0 0 1"/>
    <limit effort="450.0" lower="0" upper="0.4" velocity="0.1"/>
    <dynamics damping="100.0"/>
  </joint>
  <link name="head_pan_link">
    <inertial>
      <origin rpy="0 0 0" xyz="0.0321 0.0161 0.0390"/>
      <mass value="2.2556"/>
      <inertia ixx="0.0129" ixy="0.0002" ixz="0.0007" iyx="0.0002" iyy="0.0095" iyz="-0.0" izx="0.0007" izy="-0.0" izz="0.0184"/>
    </inertial>
    <visual>
      <origin rpy="0 0 0" xyz="0 0 0"/>
      <geometry>
        <mesh filename="package://fetch_description/meshes/head_pan_link.dae"/>
      </geometry>
      <material name="">
        <color rgba="0.356 0.361 0.376 1"/>
      </material>
    </visual>
    <collision>
      <origin rpy="0 0 0" xyz="0 0 0"/>
      <geometry>
        <mesh filename="package://fetch_description/meshes/head_pan_link_collision.STL"/>
      </geometry>
    </collision>
  </link>
  <joint name="head_pan_joint" type="revolute">
    <origin rpy="0 0 0" xyz="0.053125 0 0.603001417713939"/>
    <parent link="torso_lift_link"/>
    <child link="head_pan_link"/>
    <axis xyz="0 0 1"/>
    <limit effort="0.32" lower="-1.57" upper="1.57" velocity="1.57"/>
  </joint>
  <link name="head_tilt_link">
    <inertial>
      <origin rpy="0 0 0" xyz="0.0081 0.0025 0.0113"/>
      <mass value="0.9087"/>
      <inertia ixx="0.0061" ixy="-0.0" ixz="0.0002" iyx="-0.0" iyy="0.0014" iyz="-0.0001" izx="0.0002" izy="-0.0001" izz="0.0061"/>
    </inertial>
    <visual>
      <origin rpy="0 0 0" xyz="0 0 0"/>
      <geometry>
        <mesh filename="package://fetch_description/meshes/head_tilt_link.dae"/>
      </geometry>
      <material name="">
        <color rgba="0.086 0.506 0.767 1"/>
      </material>
    </visual>
    <collision>
      <origin rpy="0 0 0" xyz="0 0 0"/>
      <geometry>
        <mesh filename="package://fetch_description/meshes/head_tilt_link_collision.STL"/>
      </geometry>
    </collision>
  </link>
  <joint name="head_tilt_joint" type="revolute">
    <origin rpy="0 0 0" xyz="0.14253 0 0.057999"/>
    <parent link="head_pan_link"/>
    <child link="head_tilt_link"/>
    <axis xyz="0 1 0"/>
    <limit effort="0.68" lower="-0.76" upper="1.45" velocity="1.57"/>
  </joint>
  <link name="shoulder_pan_link">
    <inertial>
      <origin rpy="0 0 0" xyz="0.0927 -0.0056 0.0564"/>
      <mass value="2.5587"/>
      <inertia ixx="0.0043" ixy="-0.0001" ixz="0.001" iyx="-0.0001" iyy="0.0087" iyz="-0.0001" izx="0.001" izy="-0.0001" izz="0.0087"/>
    </inertial>
    <visual>
      <origin rpy="0 0 0" xyz="0 0 0"/>
      <geometry>
        <mesh filename="package://fetch_description/meshes/shoulder_pan_link.dae"/>
      </geometry>
      <material name="">
        <color rgba="1 1 1 1"/>
      </material>
    </visual>
    <collision>
      <origin rpy="0 0 0" xyz="0 0 0"/>
      <geometry>
        <mesh filename="package://fetch_description/meshes/shoulder_pan_link_collision.STL"/>
      </geometry>
    </collision>
  </link>
  <joint name="shoulder_pan_joint" type="revolute">
    <origin rpy="0 0 0" xyz="0.119525 0 0.34858"/>
    <parent link="torso_lift_link"/>
    <child link="shoulder_pan_link"/>
    <axis xyz="0 0 1"/>
    <limit effort="33.82" lower="-1.6056" upper="1.6056" velocity="1.256"/>
  </joint>
  <link name="shoulder_lift_link">
    <inertial>
      <origin rpy="0 0 0" xyz="0.1432 0.0072 -0.0001"/>
      <mass value="2.6615"/>
      <inertia ixx="0.0028" ixy="-0.0021" ixz="-0.0" iyx="-0.0021" iyy="0.0111" iyz="-0.0" izx="-0.0" izy="-0.0" izz="0.0112"/>
    </inertial>
    <visual>
      <origin rpy="0 0 0" xyz="0 0 0"/>
      <geometry>
        <mesh filename="package://fetch_description/meshes/shoulder_lift_link.dae"/>
      </geometry>
      <material name="">
        <color rgba="0.086 0.506 0.767 1"/>
      </material>
    </visual>
    <collision>
      <origin rpy="0 0 0" xyz="0 0 0"/>
      <geometry>
        <mesh filename="package://fetch_description/meshes/shoulder_lift_link_collision.STL"/>
      </geometry>
    </collision>
  </link>
  <joint name="shoulder_lift_joint" type="revolute">
    <origin rpy="0 0 0" xyz="0.117 0 0.0599999999999999"/>
    <parent link="shoulder_pan_link"/>
    <child link="shoulder_lift_link"/>
    <axis xyz="0 1 0"/>
    <limit effort="131.76" lower="-1.221" upper="1.518" velocity="1.454"/>
  </joint>
  <link name="upperarm_roll_link">
    <inertial>
      <origin rpy="0 0 0" xyz="0.1165 0.0014 0.0000"/>
      <mass value="2.3311"/>
      <inertia ixx="0.0019" ixy="-0.0001" ixz="0.0" iyx="-0.0001" iyy="0.0045" iyz="0.0" izx="0.0" izy="0.0" izz="0.0047"/>
    </inertial>
    <visual>
      <origin rpy="0 0 0" xyz="0 0 0"/>
      <geometry>
        <mesh filename="package://fetch_description/meshes/upperarm_roll_link.dae"/>
      </geometry>
      <material name="">
        <color rgba="1 1 1 1"/>
      </material>
    </visual>
    <collision>
      <origin rpy="0 0 0" xyz="0 0 0"/>
      <geometry>
        <mesh filename="package://fetch_description/meshes/upperarm_roll_link_collision.STL"/>
      </geometry>
    </collision>
  </link>
  <joint name="upperarm_roll_joint" type="continuous">
    <origin rpy="0 0 0" xyz="0.219 0 0"/>
    <parent link="shoulder_lift_link"/>
    <child link="upperarm_roll_link"/>
    <axis xyz="1 0 0"/>
    <limit effort="76.94" velocity="1.571"/>
  </joint>
  <link name="elbow_flex_link">
    <inertial>
      <origin rpy="0 0 0" xyz="0.1279 0.0073 0.0000"/>
      <mass value="2.1299"/>
      <inertia ixx="0.0024" ixy="-0.0016" ixz="0.0" iyx="-0.0016" iyy="0.0082" iyz="-0.0" izx="0.0" izy="-0.0" izz="0.0084"/>
    </inertial>
    <visual>
      <origin rpy="0 0 0" xyz="0 0 0"/>
      <geometry>
        <mesh filename="package://fetch_description/meshes/elbow_flex_link.dae"/>
      </geometry>
      <material name="">
        <color rgba="0.086 0.506 0.767 1"/>
      </material>
    </visual>
    <collision>
      <origin rpy="0 0 0" xyz="0 0 0"/>
      <geometry>
        <mesh filename="package://fetch_description/meshes/elbow_flex_link_collision.STL"/>
      </geometry>
    </collision>
  </link>
  <joint name="elbow_flex_joint" type="revolute">
    <origin rpy="0 0 0" xyz="0.133 0 0"/>
    <parent link="upperarm_roll_link"/>
    <child link="elbow_flex_link"/>
    <axis xyz="0 1 0"/>
    <limit effort="66.18" lower="-2.251" upper="2.251" velocity="1.521"/>
  </joint>
  <link name="forearm_roll_link">
    <inertial>
      <origin rpy="0 0 0" xyz="0.1097 -0.0266 0.0000"/>
      <mass value="1.6563"/>
      <inertia ixx="0.0016" ixy="-0.0003" ixz="0.0" iyx="-0.0003" iyy="0.003" iyz="-0.0" izx="0.0" izy="-0.0" izz="0.0035"/>
    </inertial>
    <visual>
      <origin rpy="0 0 0" xyz="0 0 0"/>
      <geometry>
        <mesh filename="package://fetch_description/meshes/forearm_roll_link.dae"/>
      </geometry>
      <material name="">
        <color rgba="1 1 1 1"/>
      </material>
    </visual>
    <collision>
      <origin rpy="0 0 0" xyz="0 0 0"/>
      <geometry>
        <mesh filename="package://fetch_description/meshes/forearm_roll_link_collision.STL"/>
      </geometry>
    </collision>
  </link>
  <joint name="forearm_roll_joint" type="continuous">
    <origin rpy="0 0 0" xyz="0.197 0 0"/>
    <parent link="elbow_flex_link"/>
    <child link="forearm_roll_link"/>
    <axis xyz="1 0 0"/>
    <limit effort="29.35" velocity="1.571"/>
  </joint>
  <link name="wrist_flex_link">
    <inertial>
      <origin rpy="0 0 0" xyz="0.0882 0.0009 -0.0001"/>
      <mass value="1.725"/>
      <inertia ixx="0.0018" ixy="-0.0001" ixz="-0.0" iyx="-0.0001" iyy="0.0042" iyz="0.0" izx="-0.0" izy="0.0" izz="0.0042"/>
    </inertial>
    <visual>
      <origin rpy="0 0 0" xyz="0 0 0"/>
      <geometry>
        <mesh filename="package://fetch_description/meshes/wrist_flex_link.dae"/>
      </geometry>
      <material name="">
        <color rgba="0.086 0.506 0.767 1"/>
      </material>
    </visual>
    <collision>
      <origin rpy="0 0 0" xyz="0 0 0"/>
      <geometry>
        <mesh filename="package://fetch_description/meshes/wrist_flex_link_collision.STL"/>
      </geometry>
    </collision>
  </link>
  <joint name="wrist_flex_joint" type="revolute">
    <origin rpy="0 0 0" xyz="0.1245 0 0"/>
    <parent link="forearm_roll_link"/>
    <child link="wrist_flex_link"/>
    <axis xyz="0 1 0"/>
    <limit effort="25.7" lower="-2.18" upper="2.18" velocity="2.268"/>
  </joint>
  <link name="wrist_roll_link">
    <inertial>
      <origin rpy="0 0 0" xyz="0.0095 0.0004 -0.0002"/>
      <mass value="0.1354"/>
      <inertia ixx="0.0001" ixy="0.0" ixz="0.0" iyx="0.0" iyy="0.0001" iyz="0.0" izx="0.0" izy="0.0" izz="0.0001"/>
    </inertial>
    <visual>
      <origin rpy="0 0 0" xyz="0 0 0"/>
      <geometry>
        <mesh filename="package://fetch_description/meshes/wrist_roll_link.dae"/>
      </geometry>
      <material name="">
        <color rgba="1 1 1 1"/>
      </material>
    </visual>
    <collision>
      <origin rpy="0 0 0" xyz="0 0 0"/>
      <geometry>
        <mesh filename="package://fetch_description/meshes/wrist_roll_link_collision.STL"/>
      </geometry>
    </collision>
  </link>
  <joint name="wrist_roll_joint" type="continuous">
    <origin rpy="0 0 0" xyz="0.1385 0 0"/>
    <parent link="wrist_flex_link"/>
    <child link="wrist_roll_link"/>
    <axis xyz="1 0 0"/>
    <limit effort="7.36" velocity="2.268"/>
  </joint>
  <joint name="gripper_axis" type="fixed">
    <origin rpy="0 0 0" xyz="0.16645 0 0"/>
    <parent link="wrist_roll_link"/>
    <child link="palm"/>
    <axis xyz="0 1 0"/>
  </joint>
  <link name="bellows_link">
    <inertial>
      <origin rpy="0 0 0" xyz="0.0191320000286228 -1.67219873481315E-16 -0.134861625443387"/>
      <mass value="0.169374038216602"/>
      <inertia ixx="0.00331159128762117" ixy="-8.9230964321455E-18" ixz="-5.38622201018293E-08" iyy="0.00174447292786627" iyz="-8.06964979976371E-17" izz="0.00169417568121457"/>
    </inertial>
    <visual>
      <origin rpy="0 0 0" xyz="0 0 0"/>
      <geometry>
        <mesh filename="package://fetch_description/meshes/bellows_link.STL"/>
      </geometry>
      <material name="">
        <color rgba="0 0 0 1"/>
      </material>
    </visual>
    <collision>
      <origin rpy="0 0 0" xyz="0 0 0"/>
      <geometry>
        <mesh filename="package://fetch_description/meshes/bellows_link_collision.STL"/>
      </geometry>
    </collision>
  </link>
  <joint name="bellows_joint" type="prismatic">
    <origin rpy="0 0 0" xyz="0 0 0"/>
    <parent link="torso_lift_link"/>
    <child link="bellows_link"/>
    <axis xyz="0 0 -1"/>
    <limit effort="5.0" lower="0" upper="0.4" velocity="0.1"/>
  </joint>
  <link name="bellows_link2">
    <inertial>
      <origin rpy="0 0 0" xyz="0.0191320000286228 -1.67219873481315E-16 -0.134861625443387"/>
      <mass value="0.169374038216602"/>
      <inertia ixx="0.00331159128762117" ixy="-8.9230964321455E-18" ixz="-5.38622201018293E-08" iyy="0.00174447292786627" iyz="-8.06964979976371E-17" izz="0.00169417568121457"/>
    </inertial>
    <visual>
      <origin rpy="0 0 0" xyz="0 0 0"/>
      <geometry>
        <mesh filename="package://fetch_description/meshes/bellows_link.STL"/>
      </geometry>
      <material name="">
        <color rgba="0 0 0 1"/>
      </material>
    </visual>
    <collision>
      <origin rpy="0 0 0" xyz="0 0 0"/>
      <geometry>
        <mesh filename="package://fetch_description/meshes/bellows_link_collision.STL"/>
      </geometry>
    </collision>
  </link>
  <joint name="bellows_joint2" type="fixed">
    <origin rpy="0 0 0" xyz="0 0 0"/>
    <parent link="torso_lift_link"/>
    <child link="bellows_link2"/>
  </joint>
  <link name="torso_fixed_link">
    <inertial>
      <origin rpy="0 0 0" xyz="-0.0722 0.0057 0.2656"/>
      <mass value="13.2775"/>
      <inertia ixx="0.3861" ixy="0.0015" ixz="-0.0102" iyx="0.0015" iyy="0.3388" iyz="0.0117" izx="-0.0102" izy="0.0117" izz="0.1018"/>
    </inertial>
    <visual>
      <origin rpy="0 0 0" xyz="0 0 0"/>
      <geometry>
        <mesh filename="package://fetch_description/meshes/torso_fixed_link.dae"/>
      </geometry>
      <material name="">
        <color rgba="0.086 0.506 0.767 1"/>
      </material>
    </visual>
    <collision>
      <origin rpy="0 0 0" xyz="0 0 0"/>
      <geometry>
        <mesh filename="package://fetch_description/meshes/torso_fixed_link.STL"/>
      </geometry>
    </collision>
  </link>
  <joint name="torso_fixed_joint" type="fixed">
    <origin rpy="-6.12303176911189E-17 0 0" xyz="-0.086875 0 0.377425"/>
    <parent link="base_link"/>
    <child link="torso_fixed_link"/>
    <axis xyz="0 1 0"/>
  </joint>
  <link name="head_camera_link"/>
  <joint name="head_camera_joint" type="fixed">
    <origin rpy="0 0 0" xyz="0.055 0 0.0225"/>
    <parent link="head_tilt_link"/>
    <child link="head_camera_link"/>
  </joint>
  <link name="head_camera_rgb_frame"/>
  <joint name="head_camera_rgb_joint" type="fixed">
    <origin rpy="0 0 0" xyz="0 0.02 0"/>
    <parent link="head_camera_link"/>
    <child link="head_camera_rgb_frame"/>
  </joint>
  <link name="head_camera_rgb_optical_frame"/>
  <joint name="head_camera_rgb_optical_joint" type="fixed">
    <origin rpy="-1.57079632679 0 -1.57079632679" xyz="0 0 0"/>
    <parent link="head_camera_rgb_frame"/>
    <child link="head_camera_rgb_optical_frame"/>
  </joint>
  <link name="head_camera_depth_frame"/>
  <joint name="head_camera_depth_joint" type="fixed">
    <origin rpy="0 0 0" xyz="0 0.045 0"/>
    <parent link="head_camera_link"/>
    <child link="head_camera_depth_frame"/>
  </joint>
  <link name="head_camera_depth_optical_frame"/>
  <joint name="head_camera_depth_optical_joint" type="fixed">
    <origin rpy="-1.57079632679 0 -1.57079632679" xyz="0 0 0"/>
    <parent link="head_camera_depth_frame"/>
    <child link="head_camera_depth_optical_frame"/>
  </joint>
  <!-- joint attaching parent link to robotiq hand -->
  <joint name="robotiq_hand_joint" type="fixed">
    <origin rpy="0 0 0" xyz="-0.09 -0.0001 -0.0017"/>
    <parent link="wrist_roll_link"/>
    <child link="palm"/>
  </joint>
  <!-- Insert the fingers -->
  <!-- Link list -->
  <!-- Link 0 -->
  <link name="finger_1_link_0">
    <visual>
      <origin rpy="0 0 0" xyz="0 0 0"/>
      <geometry>
        <mesh filename="package://robotiq_hand_description/meshes/s-model_articulated/visual/link_0.STL"/>
      </geometry>
      <material name="green">
        <color rgba="0 1 0 1"/>
      </material>
    </visual>
    <collision>
      <origin rpy="0 0 0" xyz="0 0 0"/>
      <geometry>
        <mesh filename="package://robotiq_hand_description/meshes/s-model_articulated/collision/link_0.STL"/>
      </geometry>
      <material name="yellow">
        <color rgba="0 1 1 1"/>
      </material>
    </collision>
    <inertial>
      <mass value="0.1"/>
      <origin xyz="-0.01 0 0"/>
      <inertia ixx="0.000018" ixy="0" ixz="0" iyy="0.000025" iyz="0" izz="0.000025"/>
    </inertial>
  </link>
  <gazebo reference="finger_1_link_0">
    <mu1>1.1</mu1>
    <mu2>1.1</mu2>
  </gazebo>
  <!-- Link 1 -->
  <link name="finger_1_link_1">
    <visual>
      <origin rpy="0 0 1.5708" xyz="0 0.05717 0"/>
      <geometry>
        <mesh filename="package://robotiq_hand_description/meshes/s-model_articulated/visual/link_1.STL"/>
      </geometry>
      <material name="green"/>
    </visual>
    <collision>
      <origin rpy="0 0 1.5708" xyz="0 0.05717 0"/>
      <geometry>
        <mesh filename="package://robotiq_hand_description/meshes/s-model_articulated/collision/link_1.STL"/>
      </geometry>
      <material name="yellow">
        <color rgba="0 1 1 1"/>
      </material>
    </collision>
    <inertial>
      <origin rpy="0 0 1.5708" xyz="0.00053 0.03218 0"/>
      <mass value="0.047"/>
      <inertia ixx="0.00000499332" ixy="0.00000091312" ixz="-0.00000000120" iyy="0.00006434531" iyz="-0.00000000007" izz="0.00006061917"/>
    </inertial>
  </link>
  <gazebo reference="finger_1_link_1">
    <mu1>1.1</mu1>
    <mu2>1.1</mu2>
    <minDepth>0.001</minDepth>
  </gazebo>
  <!-- Link 2 -->
  <link name="finger_1_link_2">
    <visual>
      <origin rpy="0 0 1.5708" xyz="0 0.03810 0.0075"/>
      <geometry>
        <mesh filename="package://robotiq_hand_description/meshes/s-model_articulated/visual/link_2.STL"/>
      </geometry>
      <material name="green"/>
    </visual>
    <collision>
      <origin rpy="0 0 1.5708" xyz="0 0.03810 0.0075"/>
      <geometry>
        <mesh filename="package://robotiq_hand_description/meshes/s-model_articulated/collision/link_2.STL"/>
      </geometry>
      <material name="yellow"/>
    </collision>
    <inertial>
      <origin rpy="0 0 1.5708" xyz="0.00048 0.02167 0.00018"/>
      <mass value="0.03284"/>
      <inertia ixx="0.00000348008" ixy="0.00000031940" ixz="0.00000013041" iyy="0.00002248123" iyz="0.00000000291" izz="0.00001986346"/>
    </inertial>
  </link>
  <gazebo reference="finger_1_link_2">
    <mu1>1.1</mu1>
    <mu2>1.1</mu2>
    <minDepth>0.001</minDepth>
  </gazebo>
  <!-- Link 3 -->
  <link name="finger_1_link_3">
    <visual>
      <origin rpy="0 0 0" xyz="0 0 0"/>
      <geometry>
        <mesh filename="package://robotiq_hand_description/meshes/s-model_articulated/visual/link_3.STL"/>
      </geometry>
      <material name="green"/>
    </visual>
    <collision>
      <origin rpy="0 0 0" xyz="0 0 0"/>
      <geometry>
        <mesh filename="package://robotiq_hand_description/meshes/s-model_articulated/collision/link_3.STL"/>
      </geometry>
      <material name="yellow"/>
    </collision>
    <inertial>
      <origin rpy="0 0 0" xyz="0.01626 0.00049 0.0002"/>
      <mass value="0.03354"/>
      <inertia ixx="0.00000305151" ixy="0.00000089792" ixz="0.00000000249" iyy="0.00001427978" iyz="-0.00000001191" izz="0.00001264126"/>
    </inertial>
  </link>
  <gazebo reference="finger_1_link_3">
    <mu1>1.1</mu1>
    <mu2>1.1</mu2>
    <minDepth>0.001</minDepth>
  </gazebo>
  <!-- Link proximal actuating hinge -->
  <link name="finger_1_link_proximal_actuating_hinge">
    <visual>
      <origin rpy="0 0 0" xyz="0.01429 0 0"/>
      <geometry>
        <box size="0.02858 .0075 .002"/>
      </geometry>
    </visual>
    <collision>
      <origin rpy="0 0 0" xyz="0.01429 0 0"/>
      <geometry>
        <box size="0.02858 .0075 .002"/>
      </geometry>
    </collision>
    <inertial>
      <origin rpy="0 0 0" xyz="0.0012 -0.00162 -0.00161"/>
      <mass value="0.02647"/>
      <inertia ixx="0.00000156447" ixy="0.000000236226" ixz="-0.00000014862" iyy="0.00000221068" iyz="-0.00000014369" izz="0.00000323175"/>
    </inertial>
  </link>
  <gazebo reference="finger_1_link_proximal_actuating_hinge">
    <mu1>1.1</mu1>
    <mu2>1.1</mu2>
  </gazebo>
  <!-- Link paraproximal actuating hinge -->
  <link name="finger_1_link_paraproximal_actuating_hinge">
    <visual>
      <origin rpy="0 0 0" xyz="0.01143 0 0"/>
      <geometry>
        <box size="0.02286 .0075 .002"/>
      </geometry>
    </visual>
    <collision>
      <origin rpy="0 0 0" xyz="0.01143 0 0"/>
      <geometry>
        <box size="0.02286 .0075 .002"/>
      </geometry>
    </collision>
    <inertial>
      <origin rpy="0 0 0" xyz="0.0064 0 0"/>
      <!-- copied from proximal_actuating_hinge -->
      <mass value="0.00362"/>
      <inertia ixx="0.00000012043" ixy="0" ixz="0" iyy="0.00000053588" iyz="0" izz="0.00000065322"/>
    </inertial>
  </link>
  <gazebo reference="finger_1_link_paraproximal_actuating_hinge">
    <mu1>1.1</mu1>
    <mu2>1.1</mu2>
  </gazebo>
  <!-- Link proximal actuating bar -->
  <link name="finger_1_link_proximal_actuating_bar">
    <visual>
      <origin rpy="0 0 0" xyz="0.026789 0 0"/>
      <geometry>
        <box size="0.05398 .0075 .002"/>
      </geometry>
    </visual>
    <collision>
      <origin rpy="0 0 0" xyz="0.026789 0 0"/>
      <geometry>
        <box size="0.05398 .0075 .002"/>
      </geometry>
    </collision>
    <inertial>
      <origin rpy="0 0 0" xyz="0.02699 -0.00122 0"/>
      <mass value="0.00659"/>
      <inertia ixx="0.00000008348" ixy="-0.0000002179" ixz="0.00000000134" iyy="0.00000719076" iyz="0" izz="0.00000718272"/>
    </inertial>
  </link>
  <gazebo reference="finger_1_link_proximal_actuating_bar">
    <mu1>1.1</mu1>
    <mu2>1.1</mu2>
  </gazebo>
  <!-- Link paraproximal bar -->
  <link name="finger_1_link_paraproximal_bar">
    <visual>
      <origin rpy="0 0 0" xyz="0.02885 0 0"/>
      <geometry>
        <box size="0.05770 .0075 .002"/>
      </geometry>
    </visual>
    <collision>
      <origin rpy="0 0 0" xyz="0.02885 0 0"/>
      <geometry>
        <box size="0.05770 .0075 .002"/>
      </geometry>
    </collision>
    <inertial>
      <origin rpy="0 0 0" xyz="0.02858 -0.00129 0"/>
      <mass value="0.00732"/>
      <inertia ixx="0.00000009065" ixy="-0.00000027047" ixz="0.00000000142" iyy="0.00000878034" iyz="0" izz="0.00000877558"/>
    </inertial>
  </link>
  <gazebo reference="finger_1_link_paraproximal_bar">
    <mu1>1.1</mu1>
    <mu2>1.1</mu2>
  </gazebo>
  <!-- Link median actuating hinge -->
  <link name="finger_1_link_median_actuating_hinge">
    <visual>
      <origin rpy="0 0 0" xyz="0 0 0"/>
      <geometry>
        <box size=".02 .02 .002"/>
      </geometry>
    </visual>
    <collision>
      <origin rpy="0 0 0" xyz="0 0 0"/>
      <geometry>
        <box size=".02 .02 .002"/>
      </geometry>
    </collision>
    <inertial>
      <origin rpy="0 0 0" xyz="0.0092 0.00514 0"/>
      <mass value="0.00359"/>
      <inertia ixx="0.00000024735" ixy="0.00000023619" ixz="0" iyy="0.00000047681" iyz="0" izz="0.00000071813"/>
    </inertial>
  </link>
  <gazebo reference="finger_1_link_median_actuating_hinge">
    <mu1>1.1</mu1>
    <mu2>1.1</mu2>
  </gazebo>
  <!-- Link median bar -->
  <link name="finger_1_link_median_bar">
    <visual>
      <origin rpy="0 0 0" xyz="0.01905 0 0"/>
      <geometry>
        <box size="0.0381 .0075 .002"/>
      </geometry>
    </visual>
    <collision>
      <origin rpy="0 0 0" xyz="0.01905 0 0"/>
      <geometry>
        <box size="0.0381 .0075 .002"/>
      </geometry>
    </collision>
    <inertial>
      <origin rpy="0 0 0" xyz="0.01905 -0.00107 0"/>
      <mass value="0.00538"/>
      <inertia ixx="0.00000006639" ixy="-0.00000010996" ixz="0.00000000094" iyy="0.00000305318" iyz="0" izz="0.00000304657"/>
    </inertial>
  </link>
  <gazebo reference="finger_1_link_median_bar">
    <mu1>1.1</mu1>
    <mu2>1.1</mu2>
  </gazebo>
  <!-- Link paramedian hinge -->
  <link name="finger_1_link_paramedian_hinge">
    <visual>
      <origin rpy="0 0 0" xyz="0 0 0"/>
      <geometry>
        <box size=".02 .02 .002"/>
      </geometry>
    </visual>
    <collision>
      <origin rpy="0 0 0" xyz="0 0 0"/>
      <geometry>
        <box size=".02 .02 .002"/>
      </geometry>
    </collision>
    <inertial>
      <origin rpy="0 0 0" xyz="-0.01025 0.00046 0"/>
      <mass value="0.00276"/>
      <inertia ixx="0.00000004213" ixy="-0.00000001491" ixz="0" iyy="0.00000050258" iyz="0" izz="0.00000054007"/>
    </inertial>
  </link>
  <gazebo reference="finger_1_link_paramedian_hinge">
    <mu1>1.1</mu1>
    <mu2>1.1</mu2>
  </gazebo>
  <!-- Link median bar underactuated -->
  <link name="finger_1_link_median_bar_underactuated">
    <visual>
      <origin rpy="0 0 0" xyz="0.01905 0 0"/>
      <geometry>
        <box size="0.0381 .0075 .002"/>
      </geometry>
    </visual>
    <collision>
      <origin rpy="0 0 0" xyz="0.01905 0 0"/>
      <geometry>
        <box size="0.0381 .0075 .002"/>
      </geometry>
    </collision>
    <inertial>
      <origin rpy="0 0 0" xyz="0.01905 -0.00107 0"/>
      <mass value="0.00538"/>
      <inertia ixx="0.00000006639" ixy="-0.00000010996" ixz="-0.00000000094" iyy="0.00000305318" iyz="0" izz="0.00000304657"/>
    </inertial>
  </link>
  <gazebo reference="finger_1_link_median_bar_underactuated">
    <mu1>1.1</mu1>
    <mu2>1.1</mu2>
  </gazebo>
  <!-- Link paradistal hinge -->
  <link name="finger_1_link_paradistal_hinge">
    <visual>
      <origin rpy="0 0 0" xyz="0 0 0"/>
      <geometry>
        <box size=".02 .02 .002"/>
      </geometry>
    </visual>
    <collision>
      <origin rpy="0 0 0" xyz="0 0 0"/>
      <geometry>
        <box size=".02 0.02 .002"/>
      </geometry>
    </collision>
    <inertial>
      <origin rpy="0 0 0" xyz="0.00548 0 0"/>
      <mass value="0.00158"/>
      <inertia ixx="0.00000001907" ixy="0" ixz="0" iyy="0.00000010970" iyz="0" izz="0.00000012610"/>
    </inertial>
  </link>
  <gazebo reference="finger_1_link_paradistal_hinge">
    <mu1>1.1</mu1>
    <mu2>1.1</mu2>
  </gazebo>
  <!-- End of link list -->
  <!-- Joint list -->
  <!-- Joint proximal actuating hinge -->
  <joint name="finger_1_joint_proximal_actuating_hinge" type="revolute">
    <parent link="finger_1_link_0"/>
    <child link="finger_1_link_proximal_actuating_hinge"/>
    <axis xyz="0 0 1"/>
    <origin rpy="0 0 -2.0906" xyz="0 0 0.01"/>
    <limit effort="100" lower="-3.1416" upper="3.1416" velocity="100"/>
  </joint>
  <gazebo reference="finger_1_joint_proximal_actuating_hinge">
    <implicitSpringDamper>1</implicitSpringDamper>
  </gazebo>
  <!-- Joint paraproximal actuating hinge -->
  <joint name="finger_1_joint_paraproximal_actuating_hinge" type="revolute">
    <parent link="finger_1_link_0"/>
    <child link="finger_1_link_paraproximal_actuating_hinge"/>
    <axis xyz="0 0 1"/>
    <origin rpy="0 0 -2.0906" xyz="0 0 -0.01"/>
    <limit effort="100" lower="-3.1416" upper="3.1416" velocity="100"/>
  </joint>
  <gazebo reference="finger_1_joint_paraproximal_actuating_hinge">
    <implicitSpringDamper>1</implicitSpringDamper>
  </gazebo>
  <!-- Joint proximal actuating bar -->
  <joint name="finger_1_joint_proximal_actuating_bar" type="revolute">
    <parent link="finger_1_link_proximal_actuating_hinge"/>
    <child link="finger_1_link_proximal_actuating_bar"/>
    <axis xyz="0 0 1"/>
    <origin rpy="0 0 1.8616" xyz="0.02858 0 0"/>
    <limit effort="100" lower="-3.1416" upper="3.1416" velocity="100"/>
  </joint>
  <gazebo reference="finger_1_joint_proximal_actuating_bar">
    <implicitSpringDamper>1</implicitSpringDamper>
  </gazebo>
  <!-- Joint paraproximal bar -->
  <joint name="finger_1_joint_paraproximal_bar" type="revolute">
    <parent link="finger_1_link_paraproximal_actuating_hinge"/>
    <child link="finger_1_link_paraproximal_bar"/>
    <axis xyz="0 0 1"/>
    <origin rpy="0 0 1.57" xyz="0.02286 0 0"/>
    <limit effort="100" lower="-3.1416" upper="3.1416" velocity="100"/>
  </joint>
  <gazebo reference="finger_1_joint_paraproximal_bar">
    <implicitSpringDamper>1</implicitSpringDamper>
  </gazebo>
  <!-- Joint median actuating hinge -->
  <joint name="finger_1_joint_median_actuating_hinge" type="revolute">
    <parent link="finger_1_link_1"/>
    <child link="finger_1_link_median_actuating_hinge"/>
    <axis xyz="0 0 1"/>
    <origin rpy="0 0 -0.37" xyz="0 0.05715 0.01"/>
    <limit effort="100" lower="-3.1416" upper="3.1416" velocity="100"/>
  </joint>
  <gazebo reference="finger_1_joint_median_actuating_hinge">
    <implicitSpringDamper>1</implicitSpringDamper>
  </gazebo>
  <!-- Joint paramedian hinge -->
  <joint name="finger_1_joint_paramedian_hinge" type="revolute">
    <parent link="finger_1_link_1"/>
    <child link="finger_1_link_paramedian_hinge"/>
    <axis xyz="0 0 1"/>
    <!-- -0.37 is hand picked, 0.9719 is hand calculated from atan(0.02381/0.01625) -->
    <origin rpy="0 0 0" xyz="0 0.05715 -0.01"/>
    <limit effort="100" lower="-3.1416" upper="3.1416" velocity="100"/>
  </joint>
  <gazebo reference="finger_1_joint_paramedian_hinge">
    <implicitSpringDamper>1</implicitSpringDamper>
  </gazebo>
  <!-- Joint median actuating hinge median bar -->
  <joint name="finger_1_joint_median_actuating_hinge_median_bar" type="revolute">
    <parent link="finger_1_link_median_actuating_hinge"/>
    <child link="finger_1_link_median_bar"/>
    <axis xyz="0 0 1"/>
    <!-- hand calc 90 deg + atan(0.01516/0.01625) -->
    <origin rpy="0 0 2.3215" xyz="0.01625 0.01516 0"/>
    <limit effort="100" lower="-3.1416" upper="3.1416" velocity="100"/>
  </joint>
  <gazebo reference="finger_1_joint_median_actuating_hinge_median_bar">
    <implicitSpringDamper>1</implicitSpringDamper>
  </gazebo>
  <!-- Joint paradistal hinge -->
  <joint name="finger_1_joint_paradistal_hinge" type="revolute">
    <parent link="finger_1_link_2"/>
    <child link="finger_1_link_paradistal_hinge"/>
    <axis xyz="0 0 1"/>
    <origin rpy="0 0 0" xyz="0 0.039 -0.01"/>
    <limit effort="100" lower="-3.1416" upper="3.1416" velocity="100"/>
  </joint>
  <gazebo reference="finger_1_joint_paradistal_hinge">
    <implicitSpringDamper>1</implicitSpringDamper>
  </gazebo>
  <!-- Joint paramedian hinge median bar underactuated -->
  <joint name="finger_1_joint_paramedian_hinge_median_bar_underactuated" type="revolute">
    <parent link="finger_1_link_paramedian_hinge"/>
    <child link="finger_1_link_median_bar_underactuated"/>
    <axis xyz="0 0 1"/>
    <!-- hand calc 90 deg + atan(0.01227/0.00329) -->
    <origin rpy="0 0 1.5708" xyz="0.01227 0.00329 0"/>
    <limit effort="100" lower="-3.1416" upper="3.1416" velocity="100"/>
  </joint>
  <gazebo reference="finger_1_joint_paramedian_hinge_median_bar_underactuated">
    <implicitSpringDamper>1</implicitSpringDamper>
  </gazebo>
  <!-- Joint 1 -->
  <joint name="finger_1_joint_1" type="revolute">
    <origin rpy="0 0 -2.0906" xyz="0 0 0"/>
    <axis xyz="0 0 1"/>
    <parent link="finger_1_link_0"/>
    <child link="finger_1_link_1"/>
    <dynamics damping="1" friction="0"/>
    <!-- Limits: [0deg.,70deg.] -->
    <limit effort="60" lower="0" upper="1.2217" velocity="-1"/>
  </joint>
  <gazebo reference="finger_1_joint_1">
    <implicitSpringDamper>1</implicitSpringDamper>
  </gazebo>
  <!-- Joint 2 -->
  <joint name="finger_1_joint_2" type="revolute">
    <parent link="finger_1_link_1"/>
    <child link="finger_1_link_2"/>
    <dynamics damping="1" friction="0"/>
    <axis xyz="0 0 1"/>
    <origin rpy="0 0 0" xyz="0 0.05715 0"/>
    <!-- Limits: [0deg.,90deg.] -->
    <limit effort="60" lower="0" upper="1.5708" velocity="-1"/>
  </joint>
  <gazebo reference="finger_1_joint_2">
    <implicitSpringDamper>1</implicitSpringDamper>
  </gazebo>
  <!-- Joint 3 -->
  <joint name="finger_1_joint_3" type="revolute">
    <parent link="finger_1_link_2"/>
    <child link="finger_1_link_3"/>
    <dynamics damping="1" friction="0"/>
    <axis xyz="0 0 1"/>
    <origin rpy="0 0 2.0906" xyz="0 0.039 0"/>
    <!-- Limits: [-38deg.,60deg.] -->
    <limit effort="60" lower="-0.6632" upper="1.0471" velocity="-1"/>
  </joint>
  <gazebo reference="finger_1_joint_3">
    <implicitSpringDamper>1</implicitSpringDamper>
  </gazebo>
  <!-- end of joint list -->
  <!-- coupling joints in sdf -->
  <gazebo>
    <joint name="finger_1_link_proximal_actuating_bar_median_actuating_hinge_couple" type="revolute">
      <parent>finger_1_link_median_actuating_hinge</parent>
      <child>finger_1_link_proximal_actuating_bar</child>
      <pose>0.05398 0 0 0 0 0</pose>
      <axis>
        <dynamics>
          <damping>0</damping>
          <friction>0</friction>
        </dynamics>
        <xyz>0 0 1</xyz>
        <use_parent_model_frame>false</use_parent_model_frame>
      </axis>
    </joint>
  </gazebo>
  <gazebo reference="finger_1_link_proximal_actuating_bar_median_actuating_hinge_couple">
    <implicitSpringDamper>1</implicitSpringDamper>
  </gazebo>
  <gazebo>
    <joint name="finger_1_link_median_bar_link_3_couple" type="revolute">
      <parent>finger_1_link_3</parent>
      <child>finger_1_link_median_bar</child>
      <pose>0.0381 0 0 0 0 0</pose>
      <axis>
        <dynamics>
          <damping>0</damping>
          <friction>0</friction>
        </dynamics>
        <xyz>0 0 1</xyz>
        <use_parent_model_frame>false</use_parent_model_frame>
      </axis>
    </joint>
  </gazebo>
  <gazebo reference="finger_1_link_median_bar_link_3_couple">
    <implicitSpringDamper>1</implicitSpringDamper>
  </gazebo>
  <gazebo>
    <joint name="finger_1_link_paramedian_bar_paradistal_hinge_couple" type="revolute">
      <parent>finger_1_link_paradistal_hinge</parent>
      <child>finger_1_link_median_bar_underactuated</child>
      <pose>0.0381 0 0 0 0 0</pose>
      <axis>
        <dynamics>
          <damping>0</damping>
          <friction>0</friction>
        </dynamics>
        <xyz>0 0 1</xyz>
        <use_parent_model_frame>false</use_parent_model_frame>
      </axis>
    </joint>
  </gazebo>
  <gazebo reference="finger_1_link_median_bar_link_3_couple">
    <implicitSpringDamper>1</implicitSpringDamper>
  </gazebo>
  <gazebo>
    <joint name="finger_1_link_paradistal_hinge_link_3_couple" type="revolute">
      <parent>finger_1_link_paradistal_hinge</parent>
      <child>finger_1_link_3</child>
      <pose>0.0381 0 0 0 0 0</pose>
      <axis>
        <dynamics>
          <damping>0</damping>
          <friction>0</friction>
        </dynamics>
        <xyz>0 0 1</xyz>
        <use_parent_model_frame>false</use_parent_model_frame>
      </axis>
    </joint>
  </gazebo>
  <gazebo reference="finger_1_link_paradistal_hinge_link_3_couple">
    <implicitSpringDamper>1</implicitSpringDamper>
  </gazebo>
  <gazebo>
    <joint name="finger_1_link_paraproximal_bar_paramedian_hinge_couple" type="revolute">
      <parent>finger_1_link_paramedian_hinge</parent>
      <child>finger_1_link_paraproximal_bar</child>
      <pose>0.05770 0 0 0 0 0</pose>
      <axis>
        <dynamics>
          <damping>0</damping>
          <friction>0</friction>
        </dynamics>
        <xyz>0 0 1</xyz>
        <use_parent_model_frame>false</use_parent_model_frame>
      </axis>
    </joint>
  </gazebo>
  <gazebo reference="finger_1_link_paraproximal_bar_paramedian_hinge_couple">
    <implicitSpringDamper>1</implicitSpringDamper>
  </gazebo>
  
 --&gt;

  
  <!-- Link list -->
  <!-- Link 0 -->
  <link name="finger_2_link_0">
    <visual>
      <origin rpy="0 0 0" xyz="0 0 0"/>
      <geometry>
        <mesh filename="package://robotiq_hand_description/meshes/s-model_articulated/visual/link_0.STL"/>
      </geometry>
      <material name="green">
        <color rgba="0 1 0 1"/>
      </material>
    </visual>
    <collision>
      <origin rpy="0 0 0" xyz="0 0 0"/>
      <geometry>
        <mesh filename="package://robotiq_hand_description/meshes/s-model_articulated/collision/link_0.STL"/>
      </geometry>
      <material name="yellow">
        <color rgba="0 1 1 1"/>
      </material>
    </collision>
    <inertial>
      <mass value="0.1"/>
      <origin xyz="-0.01 0 0"/>
      <inertia ixx="0.000018" ixy="0" ixz="0" iyy="0.000025" iyz="0" izz="0.000025"/>
    </inertial>
  </link>
  <gazebo reference="finger_2_link_0">
    <mu1>1.1</mu1>
    <mu2>1.1</mu2>
  </gazebo>
  <!-- Link 1 -->
  <link name="finger_2_link_1">
    <visual>
      <origin rpy="0 0 1.5708" xyz="0 0.05717 0"/>
      <geometry>
        <mesh filename="package://robotiq_hand_description/meshes/s-model_articulated/visual/link_1.STL"/>
      </geometry>
      <material name="green"/>
    </visual>
    <collision>
      <origin rpy="0 0 1.5708" xyz="0 0.05717 0"/>
      <geometry>
        <mesh filename="package://robotiq_hand_description/meshes/s-model_articulated/collision/link_1.STL"/>
      </geometry>
      <material name="yellow">
        <color rgba="0 1 1 1"/>
      </material>
    </collision>
    <inertial>
      <origin rpy="0 0 1.5708" xyz="0.00053 0.03218 0"/>
      <mass value="0.047"/>
      <inertia ixx="0.00000499332" ixy="0.00000091312" ixz="-0.00000000120" iyy="0.00006434531" iyz="-0.00000000007" izz="0.00006061917"/>
    </inertial>
  </link>
  <gazebo reference="finger_2_link_1">
    <mu1>1.1</mu1>
    <mu2>1.1</mu2>
    <minDepth>0.001</minDepth>
  </gazebo>
  <!-- Link 2 -->
  <link name="finger_2_link_2">
    <visual>
      <origin rpy="0 0 1.5708" xyz="0 0.03810 0.0075"/>
      <geometry>
        <mesh filename="package://robotiq_hand_description/meshes/s-model_articulated/visual/link_2.STL"/>
      </geometry>
      <material name="green"/>
    </visual>
    <collision>
      <origin rpy="0 0 1.5708" xyz="0 0.03810 0.0075"/>
      <geometry>
        <mesh filename="package://robotiq_hand_description/meshes/s-model_articulated/collision/link_2.STL"/>
      </geometry>
      <material name="yellow"/>
    </collision>
    <inertial>
      <origin rpy="0 0 1.5708" xyz="0.00048 0.02167 0.00018"/>
      <mass value="0.03284"/>
      <inertia ixx="0.00000348008" ixy="0.00000031940" ixz="0.00000013041" iyy="0.00002248123" iyz="0.00000000291" izz="0.00001986346"/>
    </inertial>
  </link>
  <gazebo reference="finger_2_link_2">
    <mu1>1.1</mu1>
    <mu2>1.1</mu2>
    <minDepth>0.001</minDepth>
  </gazebo>
  <!-- Link 3 -->
  <link name="finger_2_link_3">
    <visual>
      <origin rpy="0 0 0" xyz="0 0 0"/>
      <geometry>
        <mesh filename="package://robotiq_hand_description/meshes/s-model_articulated/visual/link_3.STL"/>
      </geometry>
      <material name="green"/>
    </visual>
    <collision>
      <origin rpy="0 0 0" xyz="0 0 0"/>
      <geometry>
        <mesh filename="package://robotiq_hand_description/meshes/s-model_articulated/collision/link_3.STL"/>
      </geometry>
      <material name="yellow"/>
    </collision>
    <inertial>
      <origin rpy="0 0 0" xyz="0.01626 0.00049 0.0002"/>
      <mass value="0.03354"/>
      <inertia ixx="0.00000305151" ixy="0.00000089792" ixz="0.00000000249" iyy="0.00001427978" iyz="-0.00000001191" izz="0.00001264126"/>
    </inertial>
  </link>
  <gazebo reference="finger_2_link_3">
    <mu1>1.1</mu1>
    <mu2>1.1</mu2>
    <minDepth>0.001</minDepth>
  </gazebo>
  <!-- Link proximal actuating hinge -->
  <link name="finger_2_link_proximal_actuating_hinge">
    <visual>
      <origin rpy="0 0 0" xyz="0.01429 0 0"/>
      <geometry>
        <box size="0.02858 .0075 .002"/>
      </geometry>
    </visual>
    <collision>
      <origin rpy="0 0 0" xyz="0.01429 0 0"/>
      <geometry>
        <box size="0.02858 .0075 .002"/>
      </geometry>
    </collision>
    <inertial>
      <origin rpy="0 0 0" xyz="0.0012 -0.00162 -0.00161"/>
      <mass value="0.02647"/>
      <inertia ixx="0.00000156447" ixy="0.000000236226" ixz="-0.00000014862" iyy="0.00000221068" iyz="-0.00000014369" izz="0.00000323175"/>
    </inertial>
  </link>
  <gazebo reference="finger_2_link_proximal_actuating_hinge">
    <mu1>1.1</mu1>
    <mu2>1.1</mu2>
  </gazebo>
  <!-- Link paraproximal actuating hinge -->
  <link name="finger_2_link_paraproximal_actuating_hinge">
    <visual>
      <origin rpy="0 0 0" xyz="0.01143 0 0"/>
      <geometry>
        <box size="0.02286 .0075 .002"/>
      </geometry>
    </visual>
    <collision>
      <origin rpy="0 0 0" xyz="0.01143 0 0"/>
      <geometry>
        <box size="0.02286 .0075 .002"/>
      </geometry>
    </collision>
    <inertial>
      <origin rpy="0 0 0" xyz="0.0064 0 0"/>
      <!-- copied from proximal_actuating_hinge -->
      <mass value="0.00362"/>
      <inertia ixx="0.00000012043" ixy="0" ixz="0" iyy="0.00000053588" iyz="0" izz="0.00000065322"/>
    </inertial>
  </link>
  <gazebo reference="finger_2_link_paraproximal_actuating_hinge">
    <mu1>1.1</mu1>
    <mu2>1.1</mu2>
  </gazebo>
  <!-- Link proximal actuating bar -->
  <link name="finger_2_link_proximal_actuating_bar">
    <visual>
      <origin rpy="0 0 0" xyz="0.026789 0 0"/>
      <geometry>
        <box size="0.05398 .0075 .002"/>
      </geometry>
    </visual>
    <collision>
      <origin rpy="0 0 0" xyz="0.026789 0 0"/>
      <geometry>
        <box size="0.05398 .0075 .002"/>
      </geometry>
    </collision>
    <inertial>
      <origin rpy="0 0 0" xyz="0.02699 -0.00122 0"/>
      <mass value="0.00659"/>
      <inertia ixx="0.00000008348" ixy="-0.0000002179" ixz="0.00000000134" iyy="0.00000719076" iyz="0" izz="0.00000718272"/>
    </inertial>
  </link>
  <gazebo reference="finger_2_link_proximal_actuating_bar">
    <mu1>1.1</mu1>
    <mu2>1.1</mu2>
  </gazebo>
  <!-- Link paraproximal bar -->
  <link name="finger_2_link_paraproximal_bar">
    <visual>
      <origin rpy="0 0 0" xyz="0.02885 0 0"/>
      <geometry>
        <box size="0.05770 .0075 .002"/>
      </geometry>
    </visual>
    <collision>
      <origin rpy="0 0 0" xyz="0.02885 0 0"/>
      <geometry>
        <box size="0.05770 .0075 .002"/>
      </geometry>
    </collision>
    <inertial>
      <origin rpy="0 0 0" xyz="0.02858 -0.00129 0"/>
      <mass value="0.00732"/>
      <inertia ixx="0.00000009065" ixy="-0.00000027047" ixz="0.00000000142" iyy="0.00000878034" iyz="0" izz="0.00000877558"/>
    </inertial>
  </link>
  <gazebo reference="finger_2_link_paraproximal_bar">
    <mu1>1.1</mu1>
    <mu2>1.1</mu2>
  </gazebo>
  <!-- Link median actuating hinge -->
  <link name="finger_2_link_median_actuating_hinge">
    <visual>
      <origin rpy="0 0 0" xyz="0 0 0"/>
      <geometry>
        <box size=".02 .02 .002"/>
      </geometry>
    </visual>
    <collision>
      <origin rpy="0 0 0" xyz="0 0 0"/>
      <geometry>
        <box size=".02 .02 .002"/>
      </geometry>
    </collision>
    <inertial>
      <origin rpy="0 0 0" xyz="0.0092 0.00514 0"/>
      <mass value="0.00359"/>
      <inertia ixx="0.00000024735" ixy="0.00000023619" ixz="0" iyy="0.00000047681" iyz="0" izz="0.00000071813"/>
    </inertial>
  </link>
  <gazebo reference="finger_2_link_median_actuating_hinge">
    <mu1>1.1</mu1>
    <mu2>1.1</mu2>
  </gazebo>
  <!-- Link median bar -->
  <link name="finger_2_link_median_bar">
    <visual>
      <origin rpy="0 0 0" xyz="0.01905 0 0"/>
      <geometry>
        <box size="0.0381 .0075 .002"/>
      </geometry>
    </visual>
    <collision>
      <origin rpy="0 0 0" xyz="0.01905 0 0"/>
      <geometry>
        <box size="0.0381 .0075 .002"/>
      </geometry>
    </collision>
    <inertial>
      <origin rpy="0 0 0" xyz="0.01905 -0.00107 0"/>
      <mass value="0.00538"/>
      <inertia ixx="0.00000006639" ixy="-0.00000010996" ixz="0.00000000094" iyy="0.00000305318" iyz="0" izz="0.00000304657"/>
    </inertial>
  </link>
  <gazebo reference="finger_2_link_median_bar">
    <mu1>1.1</mu1>
    <mu2>1.1</mu2>
  </gazebo>
  <!-- Link paramedian hinge -->
  <link name="finger_2_link_paramedian_hinge">
    <visual>
      <origin rpy="0 0 0" xyz="0 0 0"/>
      <geometry>
        <box size=".02 .02 .002"/>
      </geometry>
    </visual>
    <collision>
      <origin rpy="0 0 0" xyz="0 0 0"/>
      <geometry>
        <box size=".02 .02 .002"/>
      </geometry>
    </collision>
    <inertial>
      <origin rpy="0 0 0" xyz="-0.01025 0.00046 0"/>
      <mass value="0.00276"/>
      <inertia ixx="0.00000004213" ixy="-0.00000001491" ixz="0" iyy="0.00000050258" iyz="0" izz="0.00000054007"/>
    </inertial>
  </link>
  <gazebo reference="finger_2_link_paramedian_hinge">
    <mu1>1.1</mu1>
    <mu2>1.1</mu2>
  </gazebo>
  <!-- Link median bar underactuated -->
  <link name="finger_2_link_median_bar_underactuated">
    <visual>
      <origin rpy="0 0 0" xyz="0.01905 0 0"/>
      <geometry>
        <box size="0.0381 .0075 .002"/>
      </geometry>
    </visual>
    <collision>
      <origin rpy="0 0 0" xyz="0.01905 0 0"/>
      <geometry>
        <box size="0.0381 .0075 .002"/>
      </geometry>
    </collision>
    <inertial>
      <origin rpy="0 0 0" xyz="0.01905 -0.00107 0"/>
      <mass value="0.00538"/>
      <inertia ixx="0.00000006639" ixy="-0.00000010996" ixz="-0.00000000094" iyy="0.00000305318" iyz="0" izz="0.00000304657"/>
    </inertial>
  </link>
  <gazebo reference="finger_2_link_median_bar_underactuated">
    <mu1>1.1</mu1>
    <mu2>1.1</mu2>
  </gazebo>
  <!-- Link paradistal hinge -->
  <link name="finger_2_link_paradistal_hinge">
    <visual>
      <origin rpy="0 0 0" xyz="0 0 0"/>
      <geometry>
        <box size=".02 .02 .002"/>
      </geometry>
    </visual>
    <collision>
      <origin rpy="0 0 0" xyz="0 0 0"/>
      <geometry>
        <box size=".02 0.02 .002"/>
      </geometry>
    </collision>
    <inertial>
      <origin rpy="0 0 0" xyz="0.00548 0 0"/>
      <mass value="0.00158"/>
      <inertia ixx="0.00000001907" ixy="0" ixz="0" iyy="0.00000010970" iyz="0" izz="0.00000012610"/>
    </inertial>
  </link>
  <gazebo reference="finger_2_link_paradistal_hinge">
    <mu1>1.1</mu1>
    <mu2>1.1</mu2>
  </gazebo>
  <!-- End of link list -->
  <!-- Joint list -->
  <!-- Joint proximal actuating hinge -->
  <joint name="finger_2_joint_proximal_actuating_hinge" type="revolute">
    <parent link="finger_2_link_0"/>
    <child link="finger_2_link_proximal_actuating_hinge"/>
    <axis xyz="0 0 1"/>
    <origin rpy="0 0 -2.0906" xyz="0 0 0.01"/>
    <limit effort="100" lower="-3.1416" upper="3.1416" velocity="100"/>
  </joint>
  <gazebo reference="finger_2_joint_proximal_actuating_hinge">
    <implicitSpringDamper>1</implicitSpringDamper>
  </gazebo>
  <!-- Joint paraproximal actuating hinge -->
  <joint name="finger_2_joint_paraproximal_actuating_hinge" type="revolute">
    <parent link="finger_2_link_0"/>
    <child link="finger_2_link_paraproximal_actuating_hinge"/>
    <axis xyz="0 0 1"/>
    <origin rpy="0 0 -2.0906" xyz="0 0 -0.01"/>
    <limit effort="100" lower="-3.1416" upper="3.1416" velocity="100"/>
  </joint>
  <gazebo reference="finger_2_joint_paraproximal_actuating_hinge">
    <implicitSpringDamper>1</implicitSpringDamper>
  </gazebo>
  <!-- Joint proximal actuating bar -->
  <joint name="finger_2_joint_proximal_actuating_bar" type="revolute">
    <parent link="finger_2_link_proximal_actuating_hinge"/>
    <child link="finger_2_link_proximal_actuating_bar"/>
    <axis xyz="0 0 1"/>
    <origin rpy="0 0 1.8616" xyz="0.02858 0 0"/>
    <limit effort="100" lower="-3.1416" upper="3.1416" velocity="100"/>
  </joint>
  <gazebo reference="finger_2_joint_proximal_actuating_bar">
    <implicitSpringDamper>1</implicitSpringDamper>
  </gazebo>
  <!-- Joint paraproximal bar -->
  <joint name="finger_2_joint_paraproximal_bar" type="revolute">
    <parent link="finger_2_link_paraproximal_actuating_hinge"/>
    <child link="finger_2_link_paraproximal_bar"/>
    <axis xyz="0 0 1"/>
    <origin rpy="0 0 1.57" xyz="0.02286 0 0"/>
    <limit effort="100" lower="-3.1416" upper="3.1416" velocity="100"/>
  </joint>
  <gazebo reference="finger_2_joint_paraproximal_bar">
    <implicitSpringDamper>1</implicitSpringDamper>
  </gazebo>
  <!-- Joint median actuating hinge -->
  <joint name="finger_2_joint_median_actuating_hinge" type="revolute">
    <parent link="finger_2_link_1"/>
    <child link="finger_2_link_median_actuating_hinge"/>
    <axis xyz="0 0 1"/>
    <origin rpy="0 0 -0.37" xyz="0 0.05715 0.01"/>
    <limit effort="100" lower="-3.1416" upper="3.1416" velocity="100"/>
  </joint>
  <gazebo reference="finger_2_joint_median_actuating_hinge">
    <implicitSpringDamper>1</implicitSpringDamper>
  </gazebo>
  <!-- Joint paramedian hinge -->
  <joint name="finger_2_joint_paramedian_hinge" type="revolute">
    <parent link="finger_2_link_1"/>
    <child link="finger_2_link_paramedian_hinge"/>
    <axis xyz="0 0 1"/>
    <!-- -0.37 is hand picked, 0.9719 is hand calculated from atan(0.02381/0.01625) -->
    <origin rpy="0 0 0" xyz="0 0.05715 -0.01"/>
    <limit effort="100" lower="-3.1416" upper="3.1416" velocity="100"/>
  </joint>
  <gazebo reference="finger_2_joint_paramedian_hinge">
    <implicitSpringDamper>1</implicitSpringDamper>
  </gazebo>
  <!-- Joint median actuating hinge median bar -->
  <joint name="finger_2_joint_median_actuating_hinge_median_bar" type="revolute">
    <parent link="finger_2_link_median_actuating_hinge"/>
    <child link="finger_2_link_median_bar"/>
    <axis xyz="0 0 1"/>
    <!-- hand calc 90 deg + atan(0.01516/0.01625) -->
    <origin rpy="0 0 2.3215" xyz="0.01625 0.01516 0"/>
    <limit effort="100" lower="-3.1416" upper="3.1416" velocity="100"/>
  </joint>
  <gazebo reference="finger_2_joint_median_actuating_hinge_median_bar">
    <implicitSpringDamper>1</implicitSpringDamper>
  </gazebo>
  <!-- Joint paradistal hinge -->
  <joint name="finger_2_joint_paradistal_hinge" type="revolute">
    <parent link="finger_2_link_2"/>
    <child link="finger_2_link_paradistal_hinge"/>
    <axis xyz="0 0 1"/>
    <origin rpy="0 0 0" xyz="0 0.039 -0.01"/>
    <limit effort="100" lower="-3.1416" upper="3.1416" velocity="100"/>
  </joint>
  <gazebo reference="finger_2_joint_paradistal_hinge">
    <implicitSpringDamper>1</implicitSpringDamper>
  </gazebo>
  <!-- Joint paramedian hinge median bar underactuated -->
  <joint name="finger_2_joint_paramedian_hinge_median_bar_underactuated" type="revolute">
    <parent link="finger_2_link_paramedian_hinge"/>
    <child link="finger_2_link_median_bar_underactuated"/>
    <axis xyz="0 0 1"/>
    <!-- hand calc 90 deg + atan(0.01227/0.00329) -->
    <origin rpy="0 0 1.5708" xyz="0.01227 0.00329 0"/>
    <limit effort="100" lower="-3.1416" upper="3.1416" velocity="100"/>
  </joint>
  <gazebo reference="finger_2_joint_paramedian_hinge_median_bar_underactuated">
    <implicitSpringDamper>1</implicitSpringDamper>
  </gazebo>
  <!-- Joint 1 -->
  <joint name="finger_2_joint_1" type="revolute">
    <origin rpy="0 0 -2.0906" xyz="0 0 0"/>
    <axis xyz="0 0 1"/>
    <parent link="finger_2_link_0"/>
    <child link="finger_2_link_1"/>
    <dynamics damping="1" friction="0"/>
    <!-- Limits: [0deg.,70deg.] -->
    <limit effort="60" lower="0" upper="1.2217" velocity="-1"/>
  </joint>
  <gazebo reference="finger_2_joint_1">
    <implicitSpringDamper>1</implicitSpringDamper>
  </gazebo>
  <!-- Joint 2 -->
  <joint name="finger_2_joint_2" type="revolute">
    <parent link="finger_2_link_1"/>
    <child link="finger_2_link_2"/>
    <dynamics damping="1" friction="0"/>
    <axis xyz="0 0 1"/>
    <origin rpy="0 0 0" xyz="0 0.05715 0"/>
    <!-- Limits: [0deg.,90deg.] -->
    <limit effort="60" lower="0" upper="1.5708" velocity="-1"/>
  </joint>
  <gazebo reference="finger_2_joint_2">
    <implicitSpringDamper>1</implicitSpringDamper>
  </gazebo>
  <!-- Joint 3 -->
  <joint name="finger_2_joint_3" type="revolute">
    <parent link="finger_2_link_2"/>
    <child link="finger_2_link_3"/>
    <dynamics damping="1" friction="0"/>
    <axis xyz="0 0 1"/>
    <origin rpy="0 0 2.0906" xyz="0 0.039 0"/>
    <!-- Limits: [-38deg.,60deg.] -->
    <limit effort="60" lower="-0.6632" upper="1.0471" velocity="-1"/>
  </joint>
  <gazebo reference="finger_2_joint_3">
    <implicitSpringDamper>1</implicitSpringDamper>
  </gazebo>
  <!-- end of joint list -->
  <!-- coupling joints in sdf -->
  <gazebo>
    <joint name="finger_2_link_proximal_actuating_bar_median_actuating_hinge_couple" type="revolute">
      <parent>finger_2_link_median_actuating_hinge</parent>
      <child>finger_2_link_proximal_actuating_bar</child>
      <pose>0.05398 0 0 0 0 0</pose>
      <axis>
        <dynamics>
          <damping>0</damping>
          <friction>0</friction>
        </dynamics>
        <xyz>0 0 1</xyz>
        <use_parent_model_frame>false</use_parent_model_frame>
      </axis>
    </joint>
  </gazebo>
  <gazebo reference="finger_2_link_proximal_actuating_bar_median_actuating_hinge_couple">
    <implicitSpringDamper>1</implicitSpringDamper>
  </gazebo>
  <gazebo>
    <joint name="finger_2_link_median_bar_link_3_couple" type="revolute">
      <parent>finger_2_link_3</parent>
      <child>finger_2_link_median_bar</child>
      <pose>0.0381 0 0 0 0 0</pose>
      <axis>
        <dynamics>
          <damping>0</damping>
          <friction>0</friction>
        </dynamics>
        <xyz>0 0 1</xyz>
        <use_parent_model_frame>false</use_parent_model_frame>
      </axis>
    </joint>
  </gazebo>
  <gazebo reference="finger_2_link_median_bar_link_3_couple">
    <implicitSpringDamper>1</implicitSpringDamper>
  </gazebo>
  <gazebo>
    <joint name="finger_2_link_paramedian_bar_paradistal_hinge_couple" type="revolute">
      <parent>finger_2_link_paradistal_hinge</parent>
      <child>finger_2_link_median_bar_underactuated</child>
      <pose>0.0381 0 0 0 0 0</pose>
      <axis>
        <dynamics>
          <damping>0</damping>
          <friction>0</friction>
        </dynamics>
        <xyz>0 0 1</xyz>
        <use_parent_model_frame>false</use_parent_model_frame>
      </axis>
    </joint>
  </gazebo>
  <gazebo reference="finger_2_link_median_bar_link_3_couple">
    <implicitSpringDamper>1</implicitSpringDamper>
  </gazebo>
  <gazebo>
    <joint name="finger_2_link_paradistal_hinge_link_3_couple" type="revolute">
      <parent>finger_2_link_paradistal_hinge</parent>
      <child>finger_2_link_3</child>
      <pose>0.0381 0 0 0 0 0</pose>
      <axis>
        <dynamics>
          <damping>0</damping>
          <friction>0</friction>
        </dynamics>
        <xyz>0 0 1</xyz>
        <use_parent_model_frame>false</use_parent_model_frame>
      </axis>
    </joint>
  </gazebo>
  <gazebo reference="finger_2_link_paradistal_hinge_link_3_couple">
    <implicitSpringDamper>1</implicitSpringDamper>
  </gazebo>
  <gazebo>
    <joint name="finger_2_link_paraproximal_bar_paramedian_hinge_couple" type="revolute">
      <parent>finger_2_link_paramedian_hinge</parent>
      <child>finger_2_link_paraproximal_bar</child>
      <pose>0.05770 0 0 0 0 0</pose>
      <axis>
        <dynamics>
          <damping>0</damping>
          <friction>0</friction>
        </dynamics>
        <xyz>0 0 1</xyz>
        <use_parent_model_frame>false</use_parent_model_frame>
      </axis>
    </joint>
  </gazebo>
  <gazebo reference="finger_2_link_paraproximal_bar_paramedian_hinge_couple">
    <implicitSpringDamper>1</implicitSpringDamper>
  </gazebo>
  
 --&gt;

  
  <!-- Link list -->
  <!-- Link 0 -->
  <link name="finger_middle_link_0">
    <visual>
      <origin rpy="0 0 0" xyz="0 0 0"/>
      <geometry>
        <mesh filename="package://robotiq_hand_description/meshes/s-model_articulated/visual/link_0.STL"/>
      </geometry>
      <material name="green">
        <color rgba="0 1 0 1"/>
      </material>
    </visual>
    <collision>
      <origin rpy="0 0 0" xyz="0 0 0"/>
      <geometry>
        <mesh filename="package://robotiq_hand_description/meshes/s-model_articulated/collision/link_0.STL"/>
      </geometry>
      <material name="yellow">
        <color rgba="0 1 1 1"/>
      </material>
    </collision>
    <inertial>
      <mass value="0.1"/>
      <origin xyz="-0.01 0 0"/>
      <inertia ixx="0.000018" ixy="0" ixz="0" iyy="0.000025" iyz="0" izz="0.000025"/>
    </inertial>
  </link>
  <gazebo reference="finger_middle_link_0">
    <mu1>1.1</mu1>
    <mu2>1.1</mu2>
  </gazebo>
  <!-- Link 1 -->
  <link name="finger_middle_link_1">
    <visual>
      <origin rpy="0 0 1.5708" xyz="0 0.05717 0"/>
      <geometry>
        <mesh filename="package://robotiq_hand_description/meshes/s-model_articulated/visual/link_1.STL"/>
      </geometry>
      <material name="green"/>
    </visual>
    <collision>
      <origin rpy="0 0 1.5708" xyz="0 0.05717 0"/>
      <geometry>
        <mesh filename="package://robotiq_hand_description/meshes/s-model_articulated/collision/link_1.STL"/>
      </geometry>
      <material name="yellow">
        <color rgba="0 1 1 1"/>
      </material>
    </collision>
    <inertial>
      <origin rpy="0 0 1.5708" xyz="0.00053 0.03218 0"/>
      <mass value="0.047"/>
      <inertia ixx="0.00000499332" ixy="0.00000091312" ixz="-0.00000000120" iyy="0.00006434531" iyz="-0.00000000007" izz="0.00006061917"/>
    </inertial>
  </link>
  <gazebo reference="finger_middle_link_1">
    <mu1>1.1</mu1>
    <mu2>1.1</mu2>
    <minDepth>0.001</minDepth>
  </gazebo>
  <!-- Link 2 -->
  <link name="finger_middle_link_2">
    <visual>
      <origin rpy="0 0 1.5708" xyz="0 0.03810 0.0075"/>
      <geometry>
        <mesh filename="package://robotiq_hand_description/meshes/s-model_articulated/visual/link_2.STL"/>
      </geometry>
      <material name="green"/>
    </visual>
    <collision>
      <origin rpy="0 0 1.5708" xyz="0 0.03810 0.0075"/>
      <geometry>
        <mesh filename="package://robotiq_hand_description/meshes/s-model_articulated/collision/link_2.STL"/>
      </geometry>
      <material name="yellow"/>
    </collision>
    <inertial>
      <origin rpy="0 0 1.5708" xyz="0.00048 0.02167 0.00018"/>
      <mass value="0.03284"/>
      <inertia ixx="0.00000348008" ixy="0.00000031940" ixz="0.00000013041" iyy="0.00002248123" iyz="0.00000000291" izz="0.00001986346"/>
    </inertial>
  </link>
  <gazebo reference="finger_middle_link_2">
    <mu1>1.1</mu1>
    <mu2>1.1</mu2>
    <minDepth>0.001</minDepth>
  </gazebo>
  <!-- Link 3 -->
  <link name="finger_middle_link_3">
    <visual>
      <origin rpy="0 0 0" xyz="0 0 0"/>
      <geometry>
        <mesh filename="package://robotiq_hand_description/meshes/s-model_articulated/visual/link_3.STL"/>
      </geometry>
      <material name="green"/>
    </visual>
    <collision>
      <origin rpy="0 0 0" xyz="0 0 0"/>
      <geometry>
        <mesh filename="package://robotiq_hand_description/meshes/s-model_articulated/collision/link_3.STL"/>
      </geometry>
      <material name="yellow"/>
    </collision>
    <inertial>
      <origin rpy="0 0 0" xyz="0.01626 0.00049 0.0002"/>
      <mass value="0.03354"/>
      <inertia ixx="0.00000305151" ixy="0.00000089792" ixz="0.00000000249" iyy="0.00001427978" iyz="-0.00000001191" izz="0.00001264126"/>
    </inertial>
  </link>
  <gazebo reference="finger_middle_link_3">
    <mu1>1.1</mu1>
    <mu2>1.1</mu2>
    <minDepth>0.001</minDepth>
  </gazebo>
  <!-- Link proximal actuating hinge -->
  <link name="finger_middle_link_proximal_actuating_hinge">
    <visual>
      <origin rpy="0 0 0" xyz="0.01429 0 0"/>
      <geometry>
        <box size="0.02858 .0075 .002"/>
      </geometry>
    </visual>
    <collision>
      <origin rpy="0 0 0" xyz="0.01429 0 0"/>
      <geometry>
        <box size="0.02858 .0075 .002"/>
      </geometry>
    </collision>
    <inertial>
      <origin rpy="0 0 0" xyz="0.0012 -0.00162 -0.00161"/>
      <mass value="0.02647"/>
      <inertia ixx="0.00000156447" ixy="0.000000236226" ixz="-0.00000014862" iyy="0.00000221068" iyz="-0.00000014369" izz="0.00000323175"/>
    </inertial>
  </link>
  <gazebo reference="finger_middle_link_proximal_actuating_hinge">
    <mu1>1.1</mu1>
    <mu2>1.1</mu2>
  </gazebo>
  <!-- Link paraproximal actuating hinge -->
  <link name="finger_middle_link_paraproximal_actuating_hinge">
    <visual>
      <origin rpy="0 0 0" xyz="0.01143 0 0"/>
      <geometry>
        <box size="0.02286 .0075 .002"/>
      </geometry>
    </visual>
    <collision>
      <origin rpy="0 0 0" xyz="0.01143 0 0"/>
      <geometry>
        <box size="0.02286 .0075 .002"/>
      </geometry>
    </collision>
    <inertial>
      <origin rpy="0 0 0" xyz="0.0064 0 0"/>
      <!-- copied from proximal_actuating_hinge -->
      <mass value="0.00362"/>
      <inertia ixx="0.00000012043" ixy="0" ixz="0" iyy="0.00000053588" iyz="0" izz="0.00000065322"/>
    </inertial>
  </link>
  <gazebo reference="finger_middle_link_paraproximal_actuating_hinge">
    <mu1>1.1</mu1>
    <mu2>1.1</mu2>
  </gazebo>
  <!-- Link proximal actuating bar -->
  <link name="finger_middle_link_proximal_actuating_bar">
    <visual>
      <origin rpy="0 0 0" xyz="0.026789 0 0"/>
      <geometry>
        <box size="0.05398 .0075 .002"/>
      </geometry>
    </visual>
    <collision>
      <origin rpy="0 0 0" xyz="0.026789 0 0"/>
      <geometry>
        <box size="0.05398 .0075 .002"/>
      </geometry>
    </collision>
    <inertial>
      <origin rpy="0 0 0" xyz="0.02699 -0.00122 0"/>
      <mass value="0.00659"/>
      <inertia ixx="0.00000008348" ixy="-0.0000002179" ixz="0.00000000134" iyy="0.00000719076" iyz="0" izz="0.00000718272"/>
    </inertial>
  </link>
  <gazebo reference="finger_middle_link_proximal_actuating_bar">
    <mu1>1.1</mu1>
    <mu2>1.1</mu2>
  </gazebo>
  <!-- Link paraproximal bar -->
  <link name="finger_middle_link_paraproximal_bar">
    <visual>
      <origin rpy="0 0 0" xyz="0.02885 0 0"/>
      <geometry>
        <box size="0.05770 .0075 .002"/>
      </geometry>
    </visual>
    <collision>
      <origin rpy="0 0 0" xyz="0.02885 0 0"/>
      <geometry>
        <box size="0.05770 .0075 .002"/>
      </geometry>
    </collision>
    <inertial>
      <origin rpy="0 0 0" xyz="0.02858 -0.00129 0"/>
      <mass value="0.00732"/>
      <inertia ixx="0.00000009065" ixy="-0.00000027047" ixz="0.00000000142" iyy="0.00000878034" iyz="0" izz="0.00000877558"/>
    </inertial>
  </link>
  <gazebo reference="finger_middle_link_paraproximal_bar">
    <mu1>1.1</mu1>
    <mu2>1.1</mu2>
  </gazebo>
  <!-- Link median actuating hinge -->
  <link name="finger_middle_link_median_actuating_hinge">
    <visual>
      <origin rpy="0 0 0" xyz="0 0 0"/>
      <geometry>
        <box size=".02 .02 .002"/>
      </geometry>
    </visual>
    <collision>
      <origin rpy="0 0 0" xyz="0 0 0"/>
      <geometry>
        <box size=".02 .02 .002"/>
      </geometry>
    </collision>
    <inertial>
      <origin rpy="0 0 0" xyz="0.0092 0.00514 0"/>
      <mass value="0.00359"/>
      <inertia ixx="0.00000024735" ixy="0.00000023619" ixz="0" iyy="0.00000047681" iyz="0" izz="0.00000071813"/>
    </inertial>
  </link>
  <gazebo reference="finger_middle_link_median_actuating_hinge">
    <mu1>1.1</mu1>
    <mu2>1.1</mu2>
  </gazebo>
  <!-- Link median bar -->
  <link name="finger_middle_link_median_bar">
    <visual>
      <origin rpy="0 0 0" xyz="0.01905 0 0"/>
      <geometry>
        <box size="0.0381 .0075 .002"/>
      </geometry>
    </visual>
    <collision>
      <origin rpy="0 0 0" xyz="0.01905 0 0"/>
      <geometry>
        <box size="0.0381 .0075 .002"/>
      </geometry>
    </collision>
    <inertial>
      <origin rpy="0 0 0" xyz="0.01905 -0.00107 0"/>
      <mass value="0.00538"/>
      <inertia ixx="0.00000006639" ixy="-0.00000010996" ixz="0.00000000094" iyy="0.00000305318" iyz="0" izz="0.00000304657"/>
    </inertial>
  </link>
  <gazebo reference="finger_middle_link_median_bar">
    <mu1>1.1</mu1>
    <mu2>1.1</mu2>
  </gazebo>
  <!-- Link paramedian hinge -->
  <link name="finger_middle_link_paramedian_hinge">
    <visual>
      <origin rpy="0 0 0" xyz="0 0 0"/>
      <geometry>
        <box size=".02 .02 .002"/>
      </geometry>
    </visual>
    <collision>
      <origin rpy="0 0 0" xyz="0 0 0"/>
      <geometry>
        <box size=".02 .02 .002"/>
      </geometry>
    </collision>
    <inertial>
      <origin rpy="0 0 0" xyz="-0.01025 0.00046 0"/>
      <mass value="0.00276"/>
      <inertia ixx="0.00000004213" ixy="-0.00000001491" ixz="0" iyy="0.00000050258" iyz="0" izz="0.00000054007"/>
    </inertial>
  </link>
  <gazebo reference="finger_middle_link_paramedian_hinge">
    <mu1>1.1</mu1>
    <mu2>1.1</mu2>
  </gazebo>
  <!-- Link median bar underactuated -->
  <link name="finger_middle_link_median_bar_underactuated">
    <visual>
      <origin rpy="0 0 0" xyz="0.01905 0 0"/>
      <geometry>
        <box size="0.0381 .0075 .002"/>
      </geometry>
    </visual>
    <collision>
      <origin rpy="0 0 0" xyz="0.01905 0 0"/>
      <geometry>
        <box size="0.0381 .0075 .002"/>
      </geometry>
    </collision>
    <inertial>
      <origin rpy="0 0 0" xyz="0.01905 -0.00107 0"/>
      <mass value="0.00538"/>
      <inertia ixx="0.00000006639" ixy="-0.00000010996" ixz="-0.00000000094" iyy="0.00000305318" iyz="0" izz="0.00000304657"/>
    </inertial>
  </link>
  <gazebo reference="finger_middle_link_median_bar_underactuated">
    <mu1>1.1</mu1>
    <mu2>1.1</mu2>
  </gazebo>
  <!-- Link paradistal hinge -->
  <link name="finger_middle_link_paradistal_hinge">
    <visual>
      <origin rpy="0 0 0" xyz="0 0 0"/>
      <geometry>
        <box size=".02 .02 .002"/>
      </geometry>
    </visual>
    <collision>
      <origin rpy="0 0 0" xyz="0 0 0"/>
      <geometry>
        <box size=".02 0.02 .002"/>
      </geometry>
    </collision>
    <inertial>
      <origin rpy="0 0 0" xyz="0.00548 0 0"/>
      <mass value="0.00158"/>
      <inertia ixx="0.00000001907" ixy="0" ixz="0" iyy="0.00000010970" iyz="0" izz="0.00000012610"/>
    </inertial>
  </link>
  <gazebo reference="finger_middle_link_paradistal_hinge">
    <mu1>1.1</mu1>
    <mu2>1.1</mu2>
  </gazebo>
  <!-- End of link list -->
  <!-- Joint list -->
  <!-- Joint proximal actuating hinge -->
  <joint name="finger_middle_joint_proximal_actuating_hinge" type="revolute">
    <parent link="finger_middle_link_0"/>
    <child link="finger_middle_link_proximal_actuating_hinge"/>
    <axis xyz="0 0 1"/>
    <origin rpy="0 0 -2.0906" xyz="0 0 0.01"/>
    <limit effort="100" lower="-3.1416" upper="3.1416" velocity="100"/>
  </joint>
  <gazebo reference="finger_middle_joint_proximal_actuating_hinge">
    <implicitSpringDamper>1</implicitSpringDamper>
  </gazebo>
  <!-- Joint paraproximal actuating hinge -->
  <joint name="finger_middle_joint_paraproximal_actuating_hinge" type="revolute">
    <parent link="finger_middle_link_0"/>
    <child link="finger_middle_link_paraproximal_actuating_hinge"/>
    <axis xyz="0 0 1"/>
    <origin rpy="0 0 -2.0906" xyz="0 0 -0.01"/>
    <limit effort="100" lower="-3.1416" upper="3.1416" velocity="100"/>
  </joint>
  <gazebo reference="finger_middle_joint_paraproximal_actuating_hinge">
    <implicitSpringDamper>1</implicitSpringDamper>
  </gazebo>
  <!-- Joint proximal actuating bar -->
  <joint name="finger_middle_joint_proximal_actuating_bar" type="revolute">
    <parent link="finger_middle_link_proximal_actuating_hinge"/>
    <child link="finger_middle_link_proximal_actuating_bar"/>
    <axis xyz="0 0 1"/>
    <origin rpy="0 0 1.8616" xyz="0.02858 0 0"/>
    <limit effort="100" lower="-3.1416" upper="3.1416" velocity="100"/>
  </joint>
  <gazebo reference="finger_middle_joint_proximal_actuating_bar">
    <implicitSpringDamper>1</implicitSpringDamper>
  </gazebo>
  <!-- Joint paraproximal bar -->
  <joint name="finger_middle_joint_paraproximal_bar" type="revolute">
    <parent link="finger_middle_link_paraproximal_actuating_hinge"/>
    <child link="finger_middle_link_paraproximal_bar"/>
    <axis xyz="0 0 1"/>
    <origin rpy="0 0 1.57" xyz="0.02286 0 0"/>
    <limit effort="100" lower="-3.1416" upper="3.1416" velocity="100"/>
  </joint>
  <gazebo reference="finger_middle_joint_paraproximal_bar">
    <implicitSpringDamper>1</implicitSpringDamper>
  </gazebo>
  <!-- Joint median actuating hinge -->
  <joint name="finger_middle_joint_median_actuating_hinge" type="revolute">
    <parent link="finger_middle_link_1"/>
    <child link="finger_middle_link_median_actuating_hinge"/>
    <axis xyz="0 0 1"/>
    <origin rpy="0 0 -0.37" xyz="0 0.05715 0.01"/>
    <limit effort="100" lower="-3.1416" upper="3.1416" velocity="100"/>
  </joint>
  <gazebo reference="finger_middle_joint_median_actuating_hinge">
    <implicitSpringDamper>1</implicitSpringDamper>
  </gazebo>
  <!-- Joint paramedian hinge -->
  <joint name="finger_middle_joint_paramedian_hinge" type="revolute">
    <parent link="finger_middle_link_1"/>
    <child link="finger_middle_link_paramedian_hinge"/>
    <axis xyz="0 0 1"/>
    <!-- -0.37 is hand picked, 0.9719 is hand calculated from atan(0.02381/0.01625) -->
    <origin rpy="0 0 0" xyz="0 0.05715 -0.01"/>
    <limit effort="100" lower="-3.1416" upper="3.1416" velocity="100"/>
  </joint>
  <gazebo reference="finger_middle_joint_paramedian_hinge">
    <implicitSpringDamper>1</implicitSpringDamper>
  </gazebo>
  <!-- Joint median actuating hinge median bar -->
  <joint name="finger_middle_joint_median_actuating_hinge_median_bar" type="revolute">
    <parent link="finger_middle_link_median_actuating_hinge"/>
    <child link="finger_middle_link_median_bar"/>
    <axis xyz="0 0 1"/>
    <!-- hand calc 90 deg + atan(0.01516/0.01625) -->
    <origin rpy="0 0 2.3215" xyz="0.01625 0.01516 0"/>
    <limit effort="100" lower="-3.1416" upper="3.1416" velocity="100"/>
  </joint>
  <gazebo reference="finger_middle_joint_median_actuating_hinge_median_bar">
    <implicitSpringDamper>1</implicitSpringDamper>
  </gazebo>
  <!-- Joint paradistal hinge -->
  <joint name="finger_middle_joint_paradistal_hinge" type="revolute">
    <parent link="finger_middle_link_2"/>
    <child link="finger_middle_link_paradistal_hinge"/>
    <axis xyz="0 0 1"/>
    <origin rpy="0 0 0" xyz="0 0.039 -0.01"/>
    <limit effort="100" lower="-3.1416" upper="3.1416" velocity="100"/>
  </joint>
  <gazebo reference="finger_middle_joint_paradistal_hinge">
    <implicitSpringDamper>1</implicitSpringDamper>
  </gazebo>
  <!-- Joint paramedian hinge median bar underactuated -->
  <joint name="finger_middle_joint_paramedian_hinge_median_bar_underactuated" type="revolute">
    <parent link="finger_middle_link_paramedian_hinge"/>
    <child link="finger_middle_link_median_bar_underactuated"/>
    <axis xyz="0 0 1"/>
    <!-- hand calc 90 deg + atan(0.01227/0.00329) -->
    <origin rpy="0 0 1.5708" xyz="0.01227 0.00329 0"/>
    <limit effort="100" lower="-3.1416" upper="3.1416" velocity="100"/>
  </joint>
  <gazebo reference="finger_middle_joint_paramedian_hinge_median_bar_underactuated">
    <implicitSpringDamper>1</implicitSpringDamper>
  </gazebo>
  <!-- Joint 1 -->
  <joint name="finger_middle_joint_1" type="revolute">
    <origin rpy="0 0 -2.0906" xyz="0 0 0"/>
    <axis xyz="0 0 1"/>
    <parent link="finger_middle_link_0"/>
    <child link="finger_middle_link_1"/>
    <dynamics damping="1" friction="0"/>
    <!-- Limits: [0deg.,70deg.] -->
    <limit effort="60" lower="0" upper="1.2217" velocity="-1"/>
  </joint>
  <gazebo reference="finger_middle_joint_1">
    <implicitSpringDamper>1</implicitSpringDamper>
  </gazebo>
  <!-- Joint 2 -->
  <joint name="finger_middle_joint_2" type="revolute">
    <parent link="finger_middle_link_1"/>
    <child link="finger_middle_link_2"/>
    <dynamics damping="1" friction="0"/>
    <axis xyz="0 0 1"/>
    <origin rpy="0 0 0" xyz="0 0.05715 0"/>
    <!-- Limits: [0deg.,90deg.] -->
    <limit effort="60" lower="0" upper="1.5708" velocity="-1"/>
  </joint>
  <gazebo reference="finger_middle_joint_2">
    <implicitSpringDamper>1</implicitSpringDamper>
  </gazebo>
  <!-- Joint 3 -->
  <joint name="finger_middle_joint_3" type="revolute">
    <parent link="finger_middle_link_2"/>
    <child link="finger_middle_link_3"/>
    <dynamics damping="1" friction="0"/>
    <axis xyz="0 0 1"/>
    <origin rpy="0 0 2.0906" xyz="0 0.039 0"/>
    <!-- Limits: [-38deg.,60deg.] -->
    <limit effort="60" lower="-0.6632" upper="1.0471" velocity="-1"/>
  </joint>
  <gazebo reference="finger_middle_joint_3">
    <implicitSpringDamper>1</implicitSpringDamper>
  </gazebo>
  <!-- end of joint list -->
  <!-- coupling joints in sdf -->
  <gazebo>
    <joint name="finger_middle_link_proximal_actuating_bar_median_actuating_hinge_couple" type="revolute">
      <parent>finger_middle_link_median_actuating_hinge</parent>
      <child>finger_middle_link_proximal_actuating_bar</child>
      <pose>0.05398 0 0 0 0 0</pose>
      <axis>
        <dynamics>
          <damping>0</damping>
          <friction>0</friction>
        </dynamics>
        <xyz>0 0 1</xyz>
        <use_parent_model_frame>false</use_parent_model_frame>
      </axis>
    </joint>
  </gazebo>
  <gazebo reference="finger_middle_link_proximal_actuating_bar_median_actuating_hinge_couple">
    <implicitSpringDamper>1</implicitSpringDamper>
  </gazebo>
  <gazebo>
    <joint name="finger_middle_link_median_bar_link_3_couple" type="revolute">
      <parent>finger_middle_link_3</parent>
      <child>finger_middle_link_median_bar</child>
      <pose>0.0381 0 0 0 0 0</pose>
      <axis>
        <dynamics>
          <damping>0</damping>
          <friction>0</friction>
        </dynamics>
        <xyz>0 0 1</xyz>
        <use_parent_model_frame>false</use_parent_model_frame>
      </axis>
    </joint>
  </gazebo>
  <gazebo reference="finger_middle_link_median_bar_link_3_couple">
    <implicitSpringDamper>1</implicitSpringDamper>
  </gazebo>
  <gazebo>
    <joint name="finger_middle_link_paramedian_bar_paradistal_hinge_couple" type="revolute">
      <parent>finger_middle_link_paradistal_hinge</parent>
      <child>finger_middle_link_median_bar_underactuated</child>
      <pose>0.0381 0 0 0 0 0</pose>
      <axis>
        <dynamics>
          <damping>0</damping>
          <friction>0</friction>
        </dynamics>
        <xyz>0 0 1</xyz>
        <use_parent_model_frame>false</use_parent_model_frame>
      </axis>
    </joint>
  </gazebo>
  <gazebo reference="finger_middle_link_median_bar_link_3_couple">
    <implicitSpringDamper>1</implicitSpringDamper>
  </gazebo>
  <gazebo>
    <joint name="finger_middle_link_paradistal_hinge_link_3_couple" type="revolute">
      <parent>finger_middle_link_paradistal_hinge</parent>
      <child>finger_middle_link_3</child>
      <pose>0.0381 0 0 0 0 0</pose>
      <axis>
        <dynamics>
          <damping>0</damping>
          <friction>0</friction>
        </dynamics>
        <xyz>0 0 1</xyz>
        <use_parent_model_frame>false</use_parent_model_frame>
      </axis>
    </joint>
  </gazebo>
  <gazebo reference="finger_middle_link_paradistal_hinge_link_3_couple">
    <implicitSpringDamper>1</implicitSpringDamper>
  </gazebo>
  <gazebo>
    <joint name="finger_middle_link_paraproximal_bar_paramedian_hinge_couple" type="revolute">
      <parent>finger_middle_link_paramedian_hinge</parent>
      <child>finger_middle_link_paraproximal_bar</child>
      <pose>0.05770 0 0 0 0 0</pose>
      <axis>
        <dynamics>
          <damping>0</damping>
          <friction>0</friction>
        </dynamics>
        <xyz>0 0 1</xyz>
        <use_parent_model_frame>false</use_parent_model_frame>
      </axis>
    </joint>
  </gazebo>
  <gazebo reference="finger_middle_link_paraproximal_bar_paramedian_hinge_couple">
    <implicitSpringDamper>1</implicitSpringDamper>
  </gazebo>
  
 --&gt;

  
  <!-- link list -->
  <!-- Link palm -->
  <link name="palm">
    <visual>
      <geometry>
        <mesh filename="package://robotiq_hand_description/meshes/s-model_articulated/visual/palm.STL"/>
      </geometry>
      <material name="green">
        <color rgba="0 1 0 1"/>
      </material>
    </visual>
    <!-- Mesh collision -->
    <!-- <collision>
          <geometry>
            <mesh filename="package://robotiq_hand_description/meshes/s-model_articulated/collision/palm.STL"/>
          </geometry>
          <material name="yellow">
            <color rgba="0 1 1 1"/>
          </material>
        </collision> -->
    <!-- Simple shape collision -->
    <collision>
      <origin rpy="0 0 0" xyz="0 0 0"/>
      <geometry>
        <box size="0.1 0.1 0.1"/>
      </geometry>
      <material name="yellow">
        <color rgba="0 1 1 1"/>
      </material>
    </collision>
    <inertial>
      <origin rpy="0 0 0" xyz="0 0 0"/>
      <mass value="1.3"/>
      <inertia ixx="0.0035" ixy="0" ixz="-0" iyy="0.0035" iyz="0" izz="0.0035"/>
    </inertial>
  </link>
  <gazebo reference="palm">
    <mu1>1.1</mu1>
    <mu2>1.1</mu2>
  </gazebo>
  <!-- End of link list -->
  <!-- Joint list -->
  <!-- Joint palm_finger_1_joint -->
  <joint name="palm_finger_1_joint" type="revolute">
    <parent link="palm"/>
    <child link="finger_1_link_0"/>
    <dynamics damping="1" friction="0"/>
    <axis xyz="0 1 0"/>
    <origin rpy="0 3.1416 -1.57" xyz="-0.0455 0.0214 0.036"/>
    <!-- Limits: [-17deg.,17deg.] -->
    <limit effort="60" lower="-0.2967" upper="0.2967" velocity="-1"/>
  </joint>
  <gazebo reference="palm_finger_1_joint">
    <implicitSpringDamper>1</implicitSpringDamper>
  </gazebo>
  <!-- Joint palm_finger_2_joint -->
  <joint name="palm_finger_2_joint" type="revolute">
    <parent link="palm"/>
    <child link="finger_2_link_0"/>
    <dynamics damping="1" friction="0"/>
    <axis xyz="0 1 0"/>
    <origin rpy="0 3.1416 -1.57" xyz="-0.0455 0.0214 -0.036"/>
    <!-- Limits: [-17deg.,17deg.] -->
    <limit effort="60" lower="-0.2967" upper="0.2967" velocity="-1"/>
  </joint>
  <gazebo reference="palm_finger_2_joint">
    <implicitSpringDamper>1</implicitSpringDamper>
  </gazebo>
  <!-- Joint palm_finger_middle_joint -->
  <joint name="palm_finger_middle_joint" type="revolute">
    <parent link="palm"/>
    <child link="finger_middle_link_0"/>
    <dynamics damping="1" friction="0"/>
    <axis xyz="0 1 0"/>
    <origin rpy="0 0 1.57" xyz="0.0455 0.0214 0"/>
    <limit effort="60" lower="0" upper="0" velocity="-1"/>
  </joint>
  <gazebo reference="palm_finger_middle_joint">
    <implicitSpringDamper>1</implicitSpringDamper>
  </gazebo>
  <!-- end of joint list -->
</robot>

